Workbook
Name NativeTimeline_Order_Date: #N/A

Sheet Case_Study
A1: Excel Dashboard Case Study Dataset
A2: Business Scenario | B2: A Bangladesh retail company wants to monitor sales, target achievement, profit, discount, delivery, and customer rating across regions, stores, products, and salespeople.
A3: Main Goal | B3: Students will build an Excel dashboard and identify business problems from data.
A4: Data Model | B4: Fact_Sales connects with Dim_Customer, Dim_Region, Dim_Store, Dim_Product, and Dim_Salesman using IDs.
A5: Important Rule 1 | B5: Customer, Store, and Salesperson IDs are region-wise. A Dhaka customer/store/salesperson will not be assigned to another region.
A6: Important Rule 2 | B6: Product category is controlled in Dim_Product, so product name and category mismatch will not happen.
A7: Important Rule 3 | B7: Customer rating is intentionally linked with delivery days. Higher delivery days usually creates lower rating.
A8: Student Task 1 | B8: Clean/check the dataset and confirm IDs are consistent.
A9: Student Task 2 | B9: Create pivot analysis: sales by region, category, month, salesperson, and store.
A10: Student Task 3 | B10: Build dashboard with KPI cards, charts, slicers, and business findings.
A11: Student Task 4 | B11: Write at least 5 business findings using Observation → Reason → Impact → Recommendation.

Sheet Dim_Region
A1: Region_ID | B1: Region_Name | C1: Region_Code | D1: Zone | E1: Main_City | F1: Regional_Manager
A2: R01 | B2: Dhaka | C2: DHA | D2: Central | E2: Dhaka | F2: Faisal Ahmed
A3: R02 | B3: Chattogram | C3: CTG | D3: South-East | E3: Chattogram | F3: Nayeem Rahman
A4: R03 | B4: Sylhet | C4: SYL | D4: North-East | E4: Sylhet | F4: Rumana Sultana
A5: R04 | B5: Rajshahi | C5: RAJ | D5: North-West | E5: Rajshahi | F5: Tanvir Hossain
A6: R05 | B6: Khulna | C6: KHL | D6: South-West | E6: Khulna | F6: Sadia Akter
A7: R06 | B7: Barishal | C7: BAR | D7: South | E7: Barishal | F7: Arif Khan
A8: R07 | B8: Rangpur | C8: RAN | D8: North | E8: Rangpur | F8: Mahmud Islam
A9: R08 | B9: Mymensingh | C9: MYM | D9: Central-North | E9: Mymensingh | F9: Nusrat Chowdhury

Sheet Dim_Customer
A1: Customer_ID | B1: Customer_Name | C1: DOB | D1: Mobile | E1: Gender | F1: Family_Members | G1: Region_ID | H1: Region_Name
A2: CUS-DHA-001 | B2: Rumana Sultana | C2: 25852 | D2: 01601543039 | E2: Male | F2: 1 | G2: R01 | H2: Dhaka
A3: CUS-DHA-002 | B3: Tamanna Hossain | C3: 38051 | D3: 01878248963 | E3: Male | F3: 6 | G3: R01 | H3: Dhaka
A4: CUS-DHA-003 | B4: Tania Chowdhury | C4: 36053 | D4: 01333150983 | E4: Male | F4: 1 | G4: R01 | H4: Dhaka
A5: CUS-DHA-004 | B5: Mahmud Ahmed | C5: 30714 | D5: 01951834738 | E5: Male | F5: 6 | G5: R01 | H5: Dhaka
A6: CUS-DHA-005 | B6: Imran Uddin | C6: 36642 | D6: 01663116566 | E6: Female | F6: 7 | G6: R01 | H6: Dhaka
A7: CUS-DHA-006 | B7: Tania Hossain | C7: 26869 | D7: 01513338726 | E7: Male | F7: 3 | G7: R01 | H7: Dhaka
A8: CUS-DHA-007 | B8: Shamim Hossain | C8: 36042 | D8: 01380132677 | E8: Male | F8: 7 | G8: R01 | H8: Dhaka
A9: CUS-DHA-008 | B9: Karim Islam | C9: 34347 | D9: 01574687234 | E9: Male | F9: 1 | G9: R01 | H9: Dhaka
A10: CUS-DHA-009 | B10: Rumana Ahmed | C10: 32875 | D10: 01778820812 | E10: Male | F10: 5 | G10: R01 | H10: Dhaka
A11: CUS-DHA-010 | B11: Shamim Khan | C11: 34749 | D11: 01499091699 | E11: Female | F11: 3 | G11: R01 | H11: Dhaka
A12: CUS-DHA-011 | B12: Nabila Chowdhury | C12: 31180 | D12: 01447510799 | E12: Male | F12: 1 | G12: R01 | H12: Dhaka
A13: CUS-DHA-012 | B13: Nayeem Rahman | C13: 28644 | D13: 01454278498 | E13: Male | F13: 6 | G13: R01 | H13: Dhaka
... A201: CUS-MYM-025 | B201: Shaila Ahmed | C201: 29702 | D201: 01706174451 | E201: Female | F201: 1 | G201: R08 | H201: Mymensingh

Sheet Dim_Store
A1: Store_ID | B1: Store_Name | C1: Region_ID | D1: Region_Name | E1: City_Area | F1: Store_Type
A2: ST-DHA-01 | B2: Dhaka Gulshan Store | C2: R01 | D2: Dhaka | E2: Gulshan | F2: Flagship
A3: ST-DHA-02 | B3: Dhaka Dhanmondi Store | C3: R01 | D3: Dhaka | E3: Dhanmondi | F3: Express
A4: ST-DHA-03 | B4: Dhaka Mirpur Store | C4: R01 | D4: Dhaka | E4: Mirpur | F4: Standard
A5: ST-DHA-04 | B5: Dhaka Uttara Store | C5: R01 | D5: Dhaka | E5: Uttara | F5: Outlet
A6: ST-DHA-05 | B6: Dhaka Motijheel Store | C6: R01 | D6: Dhaka | E6: Motijheel | F6: Mall
A7: ST-CTG-01 | B7: Chattogram Agrabad Store | C7: R02 | D7: Chattogram | E7: Agrabad | F7: Flagship
A8: ST-CTG-02 | B8: Chattogram GEC Store | C8: R02 | D8: Chattogram | E8: GEC | F8: Express
A9: ST-CTG-03 | B9: Chattogram Panchlaish Store | C9: R02 | D9: Chattogram | E9: Panchlaish | F9: Standard
A10: ST-CTG-04 | B10: Chattogram Nasirabad Store | C10: R02 | D10: Chattogram | E10: Nasirabad | F10: Outlet
A11: ST-CTG-05 | B11: Chattogram Halishahar Store | C11: R02 | D11: Chattogram | E11: Halishahar | F11: Mall
A12: ST-SYL-01 | B12: Sylhet Zindabazar Store | C12: R03 | D12: Sylhet | E12: Zindabazar | F12: Flagship
... A41: ST-MYM-05 | B41: Mymensingh Maskanda Store | C41: R08 | D41: Mymensingh | E41: Maskanda | F41: Mall

Sheet Dim_Product
A1: Product_ID | B1: Product_Name | C1: Category | D1: Sub_Category | E1: Brand | F1: Unit_Price | G1: Unit_Cost
A2: P001 | B2: Bluetooth Speaker | C2: Electronics | D2: Audio | E2: DailyPlus | F2: 3240 | G2: 2200
A3: P002 | B3: Wireless Mouse | C3: Electronics | D3: Computer Accessories | E3: DailyPlus | F3: 3340 | G3: 2270
A4: P003 | B4: Power Bank | C4: Electronics | D4: Mobile Accessories | E4: Nexus | F4: 2840 | G4: 1930
A5: P004 | B5: Smart Watch | C5: Electronics | D5: Wearable | E5: DailyPlus | F5: 3870 | G5: 2630
A6: P005 | B6: USB-C Hub | C6: Electronics | D6: Computer Accessories | E6: GreenMart | F6: 4890 | G6: 3330
A7: P006 | B7: Electric Kettle | C7: Home Appliance | D7: Kitchen | E7: SmartLife | F7: 7200 | G7: 5040
A8: P007 | B8: Rice Cooker | C8: Home Appliance | D8: Kitchen | E8: GreenMart | F8: 7430 | G8: 5200
A9: P008 | B9: Blender Machine | C9: Home Appliance | D9: Kitchen | E9: Nova | F9: 2430 | G9: 1700
A10: P009 | B10: Steam Iron | C10: Home Appliance | D10: Laundry | E10: Nova | F10: 4560 | G10: 3190
A11: P010 | B11: Table Fan | C11: Home Appliance | D11: Cooling | E11: SmartLife | F11: 3110 | G11: 2180
A12: P011 | B12: Cotton T-Shirt | C12: Fashion | D12: Men Wear | E12: Nova | F12: 1870 | G12: 1030
A13: P012 | B13: Formal Shirt | C13: Fashion | D13: Men Wear | E13: Nova | F13: 1820 | G13: 1000
... A51: P050 | B51: Bedside Table | C51: Furniture | D51: Table | E51: Prime | F51: 5870 | G51: 4230

Sheet Dim_Salesman
A1: Salesperson_ID | B1: Salesperson_Name | C1: Region_ID | D1: Region_Name | E1: Assigned_Store_ID | F1: Joining_Date | G1: Experience_Years
A2: SM-DHA-001 | B2: Mahmud Hossain | C2: R01 | D2: Dhaka | E2: ST-DHA-01 | F2: 43568 | G2: 7
A3: SM-DHA-002 | B3: Rasel Rahman | C3: R01 | D3: Dhaka | E3: ST-DHA-02 | F3: 44469 | G3: 5
A4: SM-DHA-003 | B4: Rafi Islam | C4: R01 | D4: Dhaka | E4: ST-DHA-03 | F4: 43885 | G4: 6
A5: SM-DHA-004 | B5: Tania Sultana | C5: R01 | D5: Dhaka | E5: ST-DHA-04 | F5: 43822 | G5: 7
A6: SM-DHA-005 | B6: Imran Mia | C6: R01 | D6: Dhaka | E6: ST-DHA-05 | F6: 43596 | G6: 7
A7: SM-DHA-006 | B7: Rahim Hossain | C7: R01 | D7: Dhaka | E7: ST-DHA-01 | F7: 44361 | G7: 5
A8: SM-CTG-001 | B8: Rafi Sultana | C8: R02 | D8: Chattogram | E8: ST-CTG-01 | F8: 43574 | G8: 7
A9: SM-CTG-002 | B9: Rumana Khan | C9: R02 | D9: Chattogram | E9: ST-CTG-02 | F9: 45184 | G9: 3
A10: SM-CTG-003 | B10: Rafi Akter | C10: R02 | D10: Chattogram | E10: ST-CTG-03 | F10: 44605 | G10: 4
A11: SM-CTG-004 | B11: Shakib Ahmed | C11: R02 | D11: Chattogram | E11: ST-CTG-04 | F11: 44119 | G11: 6
A12: SM-CTG-005 | B12: Nabila Mia | C12: R02 | D12: Chattogram | E12: ST-CTG-05 | F12: 44859 | G12: 4
A13: SM-CTG-006 | B13: Sadia Islam | C13: R02 | D13: Chattogram | E13: ST-CTG-01 | F13: 44347 | G13: 5
... A49: SM-MYM-006 | B49: Tanvir Chowdhury | C49: R08 | D49: Mymensingh | E49: ST-MYM-01 | F49: 44127 | G49: 6

Sheet Fact_Sales
A1: Order_ID | B1: Order_Date | C1: Customer_ID | D1: Region_ID | E1: Store_ID | F1: Salesperson_ID | G1: Product_ID | H1: Quantity_Sold | I1: Discount | J1: Target_Sales | K1: Delivery_Days | L1: Customer_Rating | M1: Product_Name | N1: Category | O1: Unit_Price | P1: Unit_Cost | Q1: Sales_Amount | R1: Total_Cost | S1: Profit | T1: Customer Name | U1: Sales Man | V1: Region | W1: Store Name
A2: ORD-00001 | B2: 45836 | C2: CUS-RAN-017 | D2: R07 | E2: ST-RAN-01 | F2: SM-RAN-006 | G2: P006 | H2: 1 | I2: 0.15 | J2: 8280 | K2: 9 | L2: =MAX(1,MIN(5,ROUND(5.2-(K2*0.32)-(I2*2.2),1))) -> 2 | M2: =_xlfn.XLOOKUP(FactSales[[#This Row],[Product_ID]],DimProduct[Product_ID],DimProduct[Product_Name]) -> Electric Kettle | N2: =_xlfn.XLOOKUP(FactSales[[#This Row],[Product_ID]],DimProduct[Product_ID],DimProduct[Category]) -> Home Appliance | O2: =_xlfn.XLOOKUP(FactSales[[#This Row],[Product_ID]],DimProduct[Product_ID],DimProduct[Unit_Price]) -> 7200 | P2: =_xlfn.XLOOKUP(FactSales[[#This Row],[Product_ID]],DimProduct[Product_ID],DimProduct[Unit_Cost]) -> 5040 | Q2: =FactSales[[#This Row],[Unit_Price]]*FactSales[[#This Row],[Quantity_Sold]] -> 7200 | R2: =FactSales[[#This Row],[Unit_Cost]]*FactSales[[#This Row],[Quantity_Sold]] -> 5040 | S2: =FactSales[[#This Row],[Sales_Amount]]-FactSales[[#This Row],[Total_Cost]] -> 2160 | T2: =_xlfn.XLOOKUP(FactSales[[#This Row],[Customer_ID]],DimCustomer[Customer_ID],DimCustomer[Customer_Name]) -> Tamanna Mia | U2: =_xlfn.XLOOKUP(FactSales[[#This Row],[Salesperson_ID]],DimSalesman[Salesperson_ID],DimSalesman[Salesperson_Name]) -> Tania Hossain | V2: =_xlfn.XLOOKUP(FactSales[[#This Row],[Region_ID]],DimRegion[Region_ID],DimRegion[Region_Name]) -> Rangpur | W2: =_xlfn.XLOOKUP(FactSales[[#This Row],[Store_ID]],DimStore[Store_ID],DimStore[Store_Name]) -> Rangpur Jahaj Company Store
A3: ORD-00002 | B3: 45801 | C3: CUS-RAJ-004 | D3: R04 | E3: ST-RAJ-04 | F3: SM-RAJ-001 | G3: P036 | H3: 1 | I3: 0 | J3: 432 | K3: 2 | L3: =MAX(1,MIN(5,ROUND(5.2-(K3*0.32)-(I3*2.2),1))) -> 4.6 | M3: =_xlfn.XLOOKUP(FactSales[[#This Row],[Product_ID]],DimProduct[Product_ID],DimProduct[Product_Name]) -> Notebook Pack | N3: =_xlfn.XLOOKUP(FactSales[[#This Row],[Product_ID]],DimProduct[Product_ID],DimProduct[Category]) -> Stationery | O3: =_xlfn.XLOOKUP(FactSales[[#This Row],[Product_ID]],DimProduct[Product_ID],DimProduct[Unit_Price]) -> 400 | P3: =_xlfn.XLOOKUP(FactSales[[#This Row],[Product_ID]],DimProduct[Product_ID],DimProduct[Unit_Cost]) -> 200 | Q3: =FactSales[[#This Row],[Unit_Price]]*FactSales[[#This Row],[Quantity_Sold]] -> 400 | R3: =FactSales[[#This Row],[Unit_Cost]]*FactSales[[#This Row],[Quantity_Sold]] -> 200 | S3: =FactSales[[#This Row],[Sales_Amount]]-FactSales[[#This Row],[Total_Cost]] -> 200 | T3: =_xlfn.XLOOKUP(FactSales[[#This Row],[Customer_ID]],DimCustomer[Customer_ID],DimCustomer[Customer_Name]) -> Jannat Islam | U3: =_xlfn.XLOOKUP(FactSales[[#This Row],[Salesperson_ID]],DimSalesman[Salesperson_ID],DimSalesman[Salesperson_Name]) -> Imran Khan | V3: =_xlfn.XLOOKUP(FactSales[[#This Row],[Region_ID]],DimRegion[Region_ID],DimRegion[Region_Name]) -> Rajshahi | W3: =_xlfn.XLOOKUP(FactSales[[#This Row],[Store_ID]],DimStore[Store_ID],DimStore[Store_Name]) -> Rajshahi Railgate Store
A4: ORD-00003 | B4: 45744 | C4: CUS-RAJ-005 | D4: R04 | E4: ST-RAJ-02 | F4: SM-RAJ-004 | G4: P009 | H4: 4 | I4: 0.08 | J4: 19699 | K4: 7 | L4: =MAX(1,MIN(5,ROUND(5.2-(K4*0.32)-(I4*2.2),1))) -> 2.8 | M4: =_xlfn.XLOOKUP(FactSales[[#This Row],[Product_ID]],DimProduct[Product_ID],DimProduct[Product_Name]) -> Steam Iron | N4: =_xlfn.XLOOKUP(FactSales[[#This Row],[Product_ID]],DimProduct[Product_ID],DimProduct[Category]) -> Home Appliance | O4: =_xlfn.XLOOKUP(FactSales[[#This Row],[Product_ID]],DimProduct[Product_ID],DimProduct[Unit_Price]) -> 4560 | P4: =_xlfn.XLOOKUP(FactSales[[#This Row],[Product_ID]],DimProduct[Product_ID],DimProduct[Unit_Cost]) -> 3190 | Q4: =FactSales[[#This Row],[Unit_Price]]*FactSales[[#This Row],[Quantity_Sold]] -> 18240 | R4: =FactSales[[#This Row],[Unit_Cost]]*FactSales[[#This Row],[Quantity_Sold]] -> 12760 | S4: =FactSales[[#This Row],[Sales_Amount]]-FactSales[[#This Row],[Total_Cost]] -> 5480 | T4: =_xlfn.XLOOKUP(FactSales[[#This Row],[Customer_ID]],DimCustomer[Customer_ID],DimCustomer[Customer_Name]) -> Tanjim Akter | U4: =_xlfn.XLOOKUP(FactSales[[#This Row],[Salesperson_ID]],DimSalesman[Salesperson_ID],DimSalesman[Salesperson_Name]) -> Farhana Rahman | V4: =_xlfn.XLOOKUP(FactSales[[#This Row],[Region_ID]],DimRegion[Region_ID],DimRegion[Region_Name]) -> Rajshahi | W4: =_xlfn.XLOOKUP(FactSales[[#This Row],[Store_ID]],DimStore[Store_ID],DimStore[Store_Name]) -> Rajshahi Kazla Store
A5: ORD-00004 | B5: 46130 | C5: CUS-MYM-005 | D5: R08 | E5: ST-MYM-01 | F5: SM-MYM-003 | G5: P003 | H5: 3 | I5: 0.15 | J5: 9202 | K5: 4 | L5: =MAX(1,MIN(5,ROUND(5.2-(K5*0.32)-(I5*2.2),1))) -> 3.6 | M5: =_xlfn.XLOOKUP(FactSales[[#This Row],[Product_ID]],DimProduct[Product_ID],DimProduct[Product_Name]) -> Power Bank | N5: =_xlfn.XLOOKUP(FactSales[[#This Row],[Product_ID]],DimProduct[Product_ID],DimProduct[Category]) -> Electronics | O5: =_xlfn.XLOOKUP(FactSales[[#This Row],[Product_ID]],DimProduct[Product_ID],DimProduct[Unit_Price]) -> 2840 | P5: =_xlfn.XLOOKUP(FactSales[[#This Row],[Product_ID]],DimProduct[Product_ID],DimProduct[Unit_Cost]) -> 1930 | Q5: =FactSales[[#This Row],[Unit_Price]]*FactSales[[#This Row],[Quantity_Sold]] -> 8520 | R5: =FactSales[[#This Row],[Unit_Cost]]*FactSales[[#This Row],[Quantity_Sold]] -> 5790 | S5: =FactSales[[#This Row],[Sales_Amount]]-FactSales[[#This Row],[Total_Cost]] -> 2730 | T5: =_xlfn.XLOOKUP(FactSales[[#This Row],[Customer_ID]],DimCustomer[Customer_ID],DimCustomer[Customer_Name]) -> Shamim Hossain | U5: =_xlfn.XLOOKUP(FactSales[[#This Row],[Salesperson_ID]],DimSalesman[Salesperson_ID],DimSalesman[Salesperson_Name]) -> Morshed Islam | V5: =_xlfn.XLOOKUP(FactSales[[#This Row],[Region_ID]],DimRegion[Region_ID],DimRegion[Region_Name]) -> Mymensingh | W5: =_xlfn.XLOOKUP(FactSales[[#This Row],[Store_ID]],DimStore[Store_ID],DimStore[Store_Name]) -> Mymensingh Ganginarpar Store
A6: ORD-00005 | B6: 45834 | C6: CUS-RAN-016 | D6: R07 | E6: ST-RAN-01 | F6: SM-RAN-004 | G6: P028 | H6: 2 | I6: 0.05 | J6: 7406 | K6: 6 | L6: =MAX(1,MIN(5,ROUND(5.2-(K6*0.32)-(I6*2.2),1))) -> 3.2 | M6: =_xlfn.XLOOKUP(FactSales[[#This Row],[Product_ID]],DimProduct[Product_ID],DimProduct[Product_Name]) -> Ladies Sandal | N6: =_xlfn.XLOOKUP(FactSales[[#This Row],[Product_ID]],DimProduct[Product_ID],DimProduct[Category]) -> Footwear | O6: =_xlfn.XLOOKUP(FactSales[[#This Row],[Product_ID]],DimProduct[Product_ID],DimProduct[Unit_Price]) -> 3220 | P6: =_xlfn.XLOOKUP(FactSales[[#This Row],[Product_ID]],DimProduct[Product_ID],DimProduct[Unit_Cost]) -> 1930 | Q6: =FactSales[[#This Row],[Unit_Price]]*FactSales[[#This Row],[Quantity_Sold]] -> 6440 | R6: =FactSales[[#This Row],[Unit_Cost]]*FactSales[[#This Row],[Quantity_Sold]] -> 3860 | S6: =FactSales[[#This Row],[Sales_Amount]]-FactSales[[#This Row],[Total_Cost]] -> 2580 | T6: =_xlfn.XLOOKUP(FactSales[[#This Row],[Customer_ID]],DimCustomer[Customer_ID],DimCustomer[Customer_Name]) -> Tamanna Mia | U6: =_xlfn.XLOOKUP(FactSales[[#This Row],[Salesperson_ID]],DimSalesman[Salesperson_ID],DimSalesman[Salesperson_Name]) -> Farhana Uddin | V6: =_xlfn.XLOOKUP(FactSales[[#This Row],[Region_ID]],DimRegion[Region_ID],DimRegion[Region_Name]) -> Rangpur | W6: =_xlfn.XLOOKUP(FactSales[[#This Row],[Store_ID]],DimStore[Store_ID],DimStore[Store_Name]) -> Rangpur Jahaj Company Store
A7: ORD-00006 | B7: 45960 | C7: CUS-SYL-002 | D7: R03 | E7: ST-SYL-05 | F7: SM-SYL-005 | G7: P023 | H7: 2 | I7: 0.12 | J7: 2482 | K7: 5 | L7: =MAX(1,MIN(5,ROUND(5.2-(K7*0.32)-(I7*2.2),1))) -> 3.3 | M7: =_xlfn.XLOOKUP(FactSales[[#This Row],[Product_ID]],DimProduct[Product_ID],DimProduct[Product_Name]) -> Body Lotion | N7: =_xlfn.XLOOKUP(FactSales[[#This Row],[Product_ID]],DimProduct[Product_ID],DimProduct[Category]) -> Beauty & Personal Care | O7: =_xlfn.XLOOKUP(FactSales[[#This Row],[Product_ID]],DimProduct[Product_ID],DimProduct[Unit_Price]) -> 1160 | P7: =_xlfn.XLOOKUP(FactSales[[#This Row],[Product_ID]],DimProduct[Product_ID],DimProduct[Unit_Cost]) -> 670 | Q7: =FactSales[[#This Row],[Unit_Price]]*FactSales[[#This Row],[Quantity_Sold]] -> 2320 | R7: =FactSales[[#This Row],[Unit_Cost]]*FactSales[[#This Row],[Quantity_Sold]] -> 1340 | S7: =FactSales[[#This Row],[Sales_Amount]]-FactSales[[#This Row],[Total_Cost]] -> 980 | T7: =_xlfn.XLOOKUP(FactSales[[#This Row],[Customer_ID]],DimCustomer[Customer_ID],DimCustomer[Customer_Name]) -> Rafi Hossain | U7: =_xlfn.XLOOKUP(FactSales[[#This Row],[Salesperson_ID]],DimSalesman[Salesperson_ID],DimSalesman[Salesperson_Name]) -> Fahim Mia | V7: =_xlfn.XLOOKUP(FactSales[[#This Row],[Region_ID]],DimRegion[Region_ID],DimRegion[Region_Name]) -> Sylhet | W7: =_xlfn.XLOOKUP(FactSales[[#This Row],[Store_ID]],DimStore[Store_ID],DimStore[Store_Name]) -> Sylhet Upashahar Store
A8: ORD-00007 | B8: 46087 | C8: CUS-MYM-002 | D8: R08 | E8: ST-MYM-01 | F8: SM-MYM-003 | G8: P009 | H8: 3 | I8: 0.1 | J8: 14774 | K8: 4 | L8: =MAX(1,MIN(5,ROUND(5.2-(K8*0.32)-(I8*2.2),1))) -> 3.7 | M8: =_xlfn.XLOOKUP(FactSales[[#This Row],[Product_ID]],DimProduct[Product_ID],DimProduct[Product_Name]) -> Steam Iron | N8: =_xlfn.XLOOKUP(FactSales[[#This Row],[Product_ID]],DimProduct[Product_ID],DimProduct[Category]) -> Home Appliance | O8: =_xlfn.XLOOKUP(FactSales[[#This Row],[Product_ID]],DimProduct[Product_ID],DimProduct[Unit_Price]) -> 4560 | P8: =_xlfn.XLOOKUP(FactSales[[#This Row],[Product_ID]],DimProduct[Product_ID],DimProduct[Unit_Cost]) -> 3190 | Q8: =FactSales[[#This Row],[Unit_Price]]*FactSales[[#This Row],[Quantity_Sold]] -> 13680 | R8: =FactSales[[#This Row],[Unit_Cost]]*FactSales[[#This Row],[Quantity_Sold]] -> 9570 | S8: =FactSales[[#This Row],[Sales_Amount]]-FactSales[[#This Row],[Total_Cost]] -> 4110 | T8: =_xlfn.XLOOKUP(FactSales[[#This Row],[Customer_ID]],DimCustomer[Customer_ID],DimCustomer[Customer_Name]) -> Karim Chowdhury | U8: =_xlfn.XLOOKUP(FactSales[[#This Row],[Salesperson_ID]],DimSalesman[Salesperson_ID],DimSalesman[Salesperson_Name]) -> Morshed Islam | V8: =_xlfn.XLOOKUP(FactSales[[#This Row],[Region_ID]],DimRegion[Region_ID],DimRegion[Region_Name]) -> Mymensingh | W8: =_xlfn.XLOOKUP(FactSales[[#This Row],[Store_ID]],DimStore[Store_ID],DimStore[Store_Name]) -> Mymensingh Ganginarpar Store
A9: ORD-00008 | B9: 46154 | C9: CUS-DHA-013 | D9: R01 | E9: ST-DHA-03 | F9: SM-DHA-004 | G9: P018 | H9: 2 | I9: 0.03 | J9: 3625 | K9: 1 | L9: =MAX(1,MIN(5,ROUND(5.2-(K9*0.32)-(I9*2.2),1))) -> 4.8 | M9: =_xlfn.XLOOKUP(FactSales[[#This Row],[Product_ID]],DimProduct[Product_ID],DimProduct[Product_Name]) -> Lentil 1kg | N9: =_xlfn.XLOOKUP(FactSales[[#This Row],[Product_ID]],DimProduct[Product_ID],DimProduct[Category]) -> Grocery | O9: =_xlfn.XLOOKUP(FactSales[[#This Row],[Product_ID]],DimProduct[Product_ID],DimProduct[Unit_Price]) -> 1710 | P9: =_xlfn.XLOOKUP(FactSales[[#This Row],[Product_ID]],DimProduct[Product_ID],DimProduct[Unit_Cost]) -> 1330 | Q9: =FactSales[[#This Row],[Unit_Price]]*FactSales[[#This Row],[Quantity_Sold]] -> 3420 | R9: =FactSales[[#This Row],[Unit_Cost]]*FactSales[[#This Row],[Quantity_Sold]] -> 2660 | S9: =FactSales[[#This Row],[Sales_Amount]]-FactSales[[#This Row],[Total_Cost]] -> 760 | T9: =_xlfn.XLOOKUP(FactSales[[#This Row],[Customer_ID]],DimCustomer[Customer_ID],DimCustomer[Customer_Name]) -> Arif Hossain | U9: =_xlfn.XLOOKUP(FactSales[[#This Row],[Salesperson_ID]],DimSalesman[Salesperson_ID],DimSalesman[Salesperson_Name]) -> Tania Sultana | V9: =_xlfn.XLOOKUP(FactSales[[#This Row],[Region_ID]],DimRegion[Region_ID],DimRegion[Region_Name]) -> Dhaka | W9: =_xlfn.XLOOKUP(FactSales[[#This Row],[Store_ID]],DimStore[Store_ID],DimStore[Store_Name]) -> Dhaka Mirpur Store
A10: ORD-00009 | B10: 45882 | C10: CUS-RAN-009 | D10: R07 | E10: ST-RAN-02 | F10: SM-RAN-001 | G10: P007 | H10: 1 | I10: 0.12 | J10: 8544 | K10: 13 | L10: =MAX(1,MIN(5,ROUND(5.2-(K10*0.32)-(I10*2.2),1))) -> 1 | M10: =_xlfn.XLOOKUP(FactSales[[#This Row],[Product_ID]],DimProduct[Product_ID],DimProduct[Product_Name]) -> Rice Cooker | N10: =_xlfn.XLOOKUP(FactSales[[#This Row],[Product_ID]],DimProduct[Product_ID],DimProduct[Category]) -> Home Appliance | O10: =_xlfn.XLOOKUP(FactSales[[#This Row],[Product_ID]],DimProduct[Product_ID],DimProduct[Unit_Price]) -> 7430 | P10: =_xlfn.XLOOKUP(FactSales[[#This Row],[Product_ID]],DimProduct[Product_ID],DimProduct[Unit_Cost]) -> 5200 | Q10: =FactSales[[#This Row],[Unit_Price]]*FactSales[[#This Row],[Quantity_Sold]] -> 7430 | R10: =FactSales[[#This Row],[Unit_Cost]]*FactSales[[#This Row],[Quantity_Sold]] -> 5200 | S10: =FactSales[[#This Row],[Sales_Amount]]-FactSales[[#This Row],[Total_Cost]] -> 2230 | T10: =_xlfn.XLOOKUP(FactSales[[#This Row],[Customer_ID]],DimCustomer[Customer_ID],DimCustomer[Customer_Name]) -> Samiha Uddin | U10: =_xlfn.XLOOKUP(FactSales[[#This Row],[Salesperson_ID]],DimSalesman[Salesperson_ID],DimSalesman[Salesperson_Name]) -> Morshed Ahmed | V10: =_xlfn.XLOOKUP(FactSales[[#This Row],[Region_ID]],DimRegion[Region_ID],DimRegion[Region_Name]) -> Rangpur | W10: =_xlfn.XLOOKUP(FactSales[[#This Row],[Store_ID]],DimStore[Store_ID],DimStore[Store_Name]) -> Rangpur Shapla Chattar Store
A11: ORD-00010 | B11: 45760 | C11: CUS-BAR-025 | D11: R06 | E11: ST-BAR-05 | F11: SM-BAR-002 | G11: P049 | H11: 1 | I11: 0.07 | J11: 4738 | K11: 9 | L11: =MAX(1,MIN(5,ROUND(5.2-(K11*0.32)-(I11*2.2),1))) -> 2.2 | M11: =_xlfn.XLOOKUP(FactSales[[#This Row],[Product_ID]],DimProduct[Product_ID],DimProduct[Product_Name]) -> Bookshelf | N11: =_xlfn.XLOOKUP(FactSales[[#This Row],[Product_ID]],DimProduct[Product_ID],DimProduct[Category]) -> Furniture | O11: =_xlfn.XLOOKUP(FactSales[[#This Row],[Product_ID]],DimProduct[Product_ID],DimProduct[Unit_Price]) -> 4230 | P11: =_xlfn.XLOOKUP(FactSales[[#This Row],[Product_ID]],DimProduct[Product_ID],DimProduct[Unit_Cost]) -> 3050 | Q11: =FactSales[[#This Row],[Unit_Price]]*FactSales[[#This Row],[Quantity_Sold]] -> 4230 | R11: =FactSales[[#This Row],[Unit_Cost]]*FactSales[[#This Row],[Quantity_Sold]] -> 3050 | S11: =FactSales[[#This Row],[Sales_Amount]]-FactSales[[#This Row],[Total_Cost]] -> 1180 | T11: =_xlfn.XLOOKUP(FactSales[[#This Row],[Customer_ID]],DimCustomer[Customer_ID],DimCustomer[Customer_Name]) -> Fahim Khan | U11: =_xlfn.XLOOKUP(FactSales[[#This Row],[Salesperson_ID]],DimSalesman[Salesperson_ID],DimSalesman[Salesperson_Name]) -> Shaila Akter | V11: =_xlfn.XLOOKUP(FactSales[[#This Row],[Region_ID]],DimRegion[Region_ID],DimRegion[Region_Name]) -> Barishal | W11: =_xlfn.XLOOKUP(FactSales[[#This Row],[Store_ID]],DimStore[Store_ID],DimStore[Store_Name]) -> Barishal Kawnia Store
A12: ORD-00011 | B12: 46055 | C12: CUS-DHA-025 | D12: R01 | E12: ST-DHA-02 | F12: SM-DHA-005 | G12: P039 | H12: 2 | I12: 0.02 | J12: 2205 | K12: 3 | L12: =MAX(1,MIN(5,ROUND(5.2-(K12*0.32)-(I12*2.2),1))) -> 4.2 | M12: =_xlfn.XLOOKUP(FactSales[[#This Row],[Product_ID]],DimProduct[Product_ID],DimProduct[Product_Name]) -> Marker Set | N12: =_xlfn.XLOOKUP(FactSales[[#This Row],[Product_ID]],DimProduct[Product_ID],DimProduct[Category]) -> Stationery | O12: =_xlfn.XLOOKUP(FactSales[[#This Row],[Product_ID]],DimProduct[Product_ID],DimProduct[Unit_Price]) -> 1040 | P12: =_xlfn.XLOOKUP(FactSales[[#This Row],[Product_ID]],DimProduct[Product_ID],DimProduct[Unit_Cost]) -> 520 | Q12: =FactSales[[#This Row],[Unit_Price]]*FactSales[[#This Row],[Quantity_Sold]] -> 2080 | R12: =FactSales[[#This Row],[Unit_Cost]]*FactSales[[#This Row],[Quantity_Sold]] -> 1040 | S12: =FactSales[[#This Row],[Sales_Amount]]-FactSales[[#This Row],[Total_Cost]] -> 1040 | T12: =_xlfn.XLOOKUP(FactSales[[#This Row],[Customer_ID]],DimCustomer[Customer_ID],DimCustomer[Customer_Name]) -> Nabila Sultana | U12: =_xlfn.XLOOKUP(FactSales[[#This Row],[Salesperson_ID]],DimSalesman[Salesperson_ID],DimSalesman[Salesperson_Name]) -> Imran Mia | V12: =_xlfn.XLOOKUP(FactSales[[#This Row],[Region_ID]],DimRegion[Region_ID],DimRegion[Region_Name]) -> Dhaka | W12: =_xlfn.XLOOKUP(FactSales[[#This Row],[Store_ID]],DimStore[Store_ID],DimStore[Store_Name]) -> Dhaka Dhanmondi Store
A13: ORD-00012 | B13: 45803 | C13: CUS-BAR-019 | D13: R06 | E13: ST-BAR-01 | F13: SM-BAR-006 | G13: P029 | H13: 3 | I13: 0.05 | J13: 9005 | K13: 7 | L13: =MAX(1,MIN(5,ROUND(5.2-(K13*0.32)-(I13*2.2),1))) -> 2.9 | M13: =_xlfn.XLOOKUP(FactSales[[#This Row],[Product_ID]],DimProduct[Product_ID],DimProduct[Product_Name]) -> Kids Sneaker | N13: =_xlfn.XLOOKUP(FactSales[[#This Row],[Product_ID]],DimProduct[Product_ID],DimProduct[Category]) -> Footwear | O13: =_xlfn.XLOOKUP(FactSales[[#This Row],[Product_ID]],DimProduct[Product_ID],DimProduct[Unit_Price]) -> 2680 | P13: =_xlfn.XLOOKUP(FactSales[[#This Row],[Product_ID]],DimProduct[Product_ID],DimProduct[Unit_Cost]) -> 1610 | Q13: =FactSales[[#This Row],[Unit_Price]]*FactSales[[#This Row],[Quantity_Sold]] -> 8040 | R13: =FactSales[[#This Row],[Unit_Cost]]*FactSales[[#This Row],[Quantity_Sold]] -> 4830 | S13: =FactSales[[#This Row],[Sales_Amount]]-FactSales[[#This Row],[Total_Cost]] -> 3210 | T13: =_xlfn.XLOOKUP(FactSales[[#This Row],[Customer_ID]],DimCustomer[Customer_ID],DimCustomer[Customer_Name]) -> Imran Chowdhury | U13: =_xlfn.XLOOKUP(FactSales[[#This Row],[Salesperson_ID]],DimSalesman[Salesperson_ID],DimSalesman[Salesperson_Name]) -> Nayeem Akter | V13: =_xlfn.XLOOKUP(FactSales[[#This Row],[Region_ID]],DimRegion[Region_ID],DimRegion[Region_Name]) -> Barishal | W13: =_xlfn.XLOOKUP(FactSales[[#This Row],[Store_ID]],DimStore[Store_ID],DimStore[Store_Name]) -> Barishal Nathullabad Store
... A1001: ORD-01000 | B1001: 45933 | C1001: CUS-KHL-007 | D1001: R05 | E1001: ST-KHL-03 | F1001: SM-KHL-006 | G1001: P048 | H1001: 1 | I1001: 0.05 | J1001: 5799 | K1001: 8 | L1001: =MAX(1,MIN(5,ROUND(5.2-(K1001*0.32)-(I1001*2.2),1))) -> 2.5 | M1001: =_xlfn.XLOOKUP(FactSales[[#This Row],[Product_ID]],DimProduct[Product_ID],DimProduct[Product_Name]) -> Shoe Rack | N1001: =_xlfn.XLOOKUP(FactSales[[#This Row],[Product_ID]],DimProduct[Product_ID],DimProduct[Category]) -> Furniture | O1001: =_xlfn.XLOOKUP(FactSales[[#This Row],[Product_ID]],DimProduct[Product_ID],DimProduct[Unit_Price]) -> 5320 | P1001: =_xlfn.XLOOKUP(FactSales[[#This Row],[Product_ID]],DimProduct[Product_ID],DimProduct[Unit_Cost]) -> 3830 | Q1001: =FactSales[[#This Row],[Unit_Price]]*FactSales[[#This Row],[Quantity_Sold]] -> 5320 | R1001: =FactSales[[#This Row],[Unit_Cost]]*FactSales[[#This Row],[Quantity_Sold]] -> 3830 | S1001: =FactSales[[#This Row],[Sales_Amount]]-FactSales[[#This Row],[Total_Cost]] -> 1490 | T1001: =_xlfn.XLOOKUP(FactSales[[#This Row],[Customer_ID]],DimCustomer[Customer_ID],DimCustomer[Customer_Name]) -> Mahmud Chowdhury | U1001: =_xlfn.XLOOKUP(FactSales[[#This Row],[Salesperson_ID]],DimSalesman[Salesperson_ID],DimSalesman[Salesperson_Name]) -> Fahim Uddin | V1001: =_xlfn.XLOOKUP(FactSales[[#This Row],[Region_ID]],DimRegion[Region_ID],DimRegion[Region_Name]) -> Khulna | W1001: =_xlfn.XLOOKUP(FactSales[[#This Row],[Store_ID]],DimStore[Store_ID],DimStore[Store_Name]) -> Khulna Daulatpur Store

Sheet Analysis
F1: KPI
D5: Total Order | E5: Total Sales | F5: Target Sales | G5: Target Achieved
D6: 1000 | E6: 10372470 | F6: 11399649 | G6: 0.9098938
J10: Count of Customer_ID | K10: Column Labels
D11: Region | E11: Total Sales | F11: Rank | G11: Target sales | H11: Target Achieved | J11: Region | K11: 1-2 | L11: 2-3 | M11: 3-4 | N11: 4-5
D12: Dhaka | E12: 1490960 | F12: 2 | G12: 1580413 | H12: 0.94339897 | J12: Dhaka | K12: 1 | L12: 2 | M12: 44 | N12: 81
D13: Sylhet | E13: 1072720 | F13: 7 | G13: 1147816 | H13: 0.93457488 | J13: Khulna | L13: 10 | M13: 65 | N13: 55
D14: Rajshahi | E14: 1330400 | F14: 4 | G14: 1436830 | H14: 0.92592721 | J14: Rajshahi | L14: 17 | M14: 74 | N14: 47
D15: Mymensingh | E15: 1064080 | F15: 8 | G15: 1149207 | H15: 0.92592544 | J15: Sylhet | L15: 5 | M15: 58 | N15: 41
D16: Khulna | E16: 1383370 | F16: 3 | G16: 1507877 | H16: 0.91742894 | J16: Mymensingh | K16: 2 | L16: 20 | M16: 58 | N16: 37
D17: Barishal | E17: 1498090 | F17: 1 | G17: 1677860 | H17: 0.89285757 | J17: Barishal | K17: 2 | L17: 41 | M17: 66 | N17: 23
D18: Chattogram | E18: 1311820 | F18: 5 | G18: 1495472 | H18: 0.87719462 | J18: Chattogram | K18: 6 | L18: 39 | M18: 64 | N18: 18
D19: Rangpur | E19: 1221030 | F19: 6 | G19: 1404174 | H19: 0.86957172 | J19: Rangpur | K19: 9 | L19: 56 | M19: 47 | N19: 12
D20: Grand Total | E20: 10372470 | G20: 11399649 | H20: 0.9098938 | J20: Grand Total | K20: 20 | L20: 190 | M20: 476 | N20: 314
D25: Region | E25: Avg Delivery Date
D26: Dhaka | E26: 2.96875 | H26: Region | I26: Total Sales | J26: Target Sales
D27: Khulna | E27: 3.7461538 | H27: Barishal | I27: 1498090 | J27: 1677860
D28: Sylhet | E28: 3.7884615 | H28: Chattogram | I28: 1311820 | J28: 1495472
D29: Rajshahi | E29: 4.2971014 | H29: Dhaka | I29: 1490960 | J29: 1580413
D30: Mymensingh | E30: 4.5641026 | H30: Khulna | I30: 1383370 | J30: 1507877
D31: Barishal | E31: 5.3787879 | H31: Mymensingh | I31: 1064080 | J31: 1149207
D32: Chattogram | E32: 5.4566929 | H32: Rajshahi | I32: 1330400 | J32: 1436830
D33: Rangpur | E33: 6.4274194 | H33: Rangpur | I33: 1221030 | J33: 1404174
D34: Grand Total | E34: 4.588 | H34: Sylhet | I34: 1072720 | J34: 1147816
D38: Salesperson_ID | E38: Sales Man | F38: Sum of Sales_Amount | H38: Total Sale by top ten sales man
D39: SM-BAR-002 | E39: Shaila Akter | F39: 300240
D40: SM-BAR-003 | E40: Rasel Uddin | F40: 358680 | H40: =SUM(F39:F48) -> 3124060
D41: SM-CTG-004 | E41: Shakib Ahmed | F41: 323880
D42: SM-CTG-005 | E42: Nabila Mia | F42: 290270 | H42: Total sales
D43: SM-DHA-001 | E43: Mahmud Hossain | F43: 316400 | H43: =GETPIVOTDATA("Total Sales",$D$5) -> 10372470
D44: SM-DHA-004 | E44: Tania Sultana | F44: 309150
D45: SM-KHL-003 | E45: Sadia Sultana | F45: 294550 | H45: Sale % by top 10 sales man | J45: Sales % by remaining sellers
D46: SM-KHL-006 | E46: Fahim Uddin | F46: 299560 | H46: =H40/H43 -> 0.30118766 | J46: =100%-H46 -> 0.69881234
D47: SM-MYM-004 | E47: Fahim Hossain | F47: 298350
D48: SM-RAJ-002 | E48: Karim Khan | F48: 332980
D49: Grand Total | F49: 3124060 | H49: ="Top 10 sales man contribute to "&TEXT(H46,"0.00%")& " sales and remaining sales man contribute to "&TEXT(J46,"0.00%")& " sales" -> Top 10 sales man contribute to 30.12% sales and remaining sales man contribute to 69.88% sales
F52: 2
D53: Region | E53: Sales Amount | F53: Target Achieved
D54: Barishal Kawnia Store | E54: 388430 | F54: 0.89285632 | H54: Top 5 Sales by Performance | J54: {=IF(F52=1,$D$53:$F$58,$D$64:$F$69)} -> Region | K54: Sales Amount | L54: Target Achieved
D55: Chattogram Nasirabad Store | E55: 364560 | F55: 0.87720016 | J55: Chattogram Agrabad Store | K55: 175790 | L55: 0.87719561
...

Sheet Dash 01

Sheet Dash02

Sheet Delivery Details
A1: Region | B1: Store Name | C1: Avg Delivery Date
A2: Dhaka | B2: Dhaka Dhanmondi Store | C2: 2.875
A3: Dhaka | B3: Dhaka Gulshan Store | C3: 2.6666667
A4: Dhaka | B4: Dhaka Mirpur Store | C4: 3.2142857
A5: Dhaka | B5: Dhaka Motijheel Store | C5: 3.28
A6: Dhaka | B6: Dhaka Uttara Store | C6: 2.7777778
A7: Dhaka Total | C7: 2.96875
A8: Khulna | B8: Khulna Boyra Store | C8: 3.68
A9: Khulna | B9: Khulna Daulatpur Store | C9: 3.4
A10: Khulna | B10: Khulna Khalishpur Store | C10: 3.6363636
A11: Khulna | B11: Khulna Shibbari Store | C11: 4.125
A12: Khulna | B12: Khulna Sonadanga Store | C12: 3.7692308
A13: Khulna Total | C13: 3.7461538
A14: Sylhet | B14: Sylhet Ambarkhana Store | C14: 3.4090909
A15: Sylhet | B15: Sylhet South Surma Store | C15: 4.173913
A16: Sylhet | B16: Sylhet Subidbazar Store | C16: 4.0555556
A17: Sylhet | B17: Sylhet Upashahar Store | C17: 3.9090909
A18: Sylhet | B18: Sylhet Zindabazar Store | C18: 3.3684211
A19: Sylhet Total | C19: 3.7884615
A20: Rajshahi | B20: Rajshahi Kazla Store | C20: 4.2564103
A21: Rajshahi | B21: Rajshahi Lakshmipur Store | C21: 4.516129
A22: Rajshahi | B22: Rajshahi Railgate Store | C22: 4.1904762
A23: Rajshahi | B23: Rajshahi Shaheb Bazar Store | C23: 4.0833333
A24: Rajshahi | B24: Rajshahi Uposhohor Store | C24: 4.3913043
A25: Rajshahi Total | C25: 4.2971014
A26: Mymensingh | B26: Mymensingh Charpara Store | C26: 5.1363636
A27: Mymensingh | B27: Mymensingh Ganginarpar Store | C27: 4.125
A28: Mymensingh | B28: Mymensingh Kewatkhali Store | C28: 4.1111111
A29: Mymensingh | B29: Mymensingh Maskanda Store | C29: 4.4642857
A30: Mymensingh | B30: Mymensingh Town Hall Store | C30: 4.92
A31: Mymensingh Total | C31: 4.5641026
A32: Barishal | B32: Barishal Chowmatha Store | C32: 5.2222222
A33: Barishal | B33: Barishal Kawnia Store | C33: 5.4444444
A34: Barishal | B34: Barishal Nathullabad Store | C34: 5.2666667
A35: Barishal | B35: Barishal Rupatali Store | C35: 5.9166667
A36: Barishal | B36: Barishal Sadar Road Store | C36: 5.0833333
A37: Barishal Total | C37: 5.3787879
A38: Chattogram | B38: Chattogram Agrabad Store | C38: 5.05
A39: Chattogram | B39: Chattogram GEC Store | C39: 5.3333333
A40: Chattogram | B40: Chattogram Halishahar Store | C40: 5.76
...

Sheet Data_Model
A1: Fact Table | B1: Key Column | C1: Dimension Table | D1: Relationship Logic | E1: Mismatch Control
A2: Fact_Sales | B2: Customer_ID | C2: Dim_Customer | D2: Many orders can belong to one customer. | E2: Fact customer is selected from same Region_ID.
A3: Fact_Sales | B3: Region_ID | C3: Dim_Region | D3: Each order belongs to one BD region/division. | E3: Region_ID controls customer, store, and salesman matching.
A4: Fact_Sales | B4: Store_ID | C4: Dim_Store | D4: Each order belongs to one store. | E4: Store is selected from order Region_ID only.
A5: Fact_Sales | B5: Product_ID | C5: Dim_Product | D5: Each order has one product. | E5: Product_Name and Category are pulled from Dim_Product.
A6: Fact_Sales | B6: Salesperson_ID | C6: Dim_Salesman | D6: Each order handled by one salesperson. | E6: Salesperson is selected from order Region_ID only.

Sheet Dashboard_Plan
A1: Business Question | B1: Metric/KPI
A2: Overall sales performance kemon? | B2: Total Sales, Total Profit, Profit Margin
A3: Kon region target miss korche? | B3: Sales vs Target, Achievement %
A4: Kon category low margin? | B4: Profit Margin %, Avg Discount
A5: Delivery delay rating affect korche? | B5: Avg Delivery Days, Avg Rating
A6: Top products er upor dependency ache? | B6: Top 5 Product Sales Share
A7: Salesman performance gap ache? | B7: Sales by Salesperson

Sheet Business_Findings
A1: Problem_Area | B1: Observation | C1: Possible_Reason | D1: Business_Impact | E1: Recommendation
A2: Target Achievement | B2: Chattogram has the lowest achievement at 77.9%. | C2: Target factor is high and actual sales are reduced by discount. | D2: Overall achievement may fall even when order volume is stable. | E2: Review region-wise target allocation and create store-wise recovery plan.
A3: Delivery & Rating | B3: Rangpur has the highest average delivery days (6.4) and average rating 2.9. | C3: Logistics or stock availability delay may be affecting customer satisfaction. | D3: Low rating can reduce repeat purchase and brand trust. | E3: Track delayed orders weekly and prioritize inventory for slow delivery regions.
A4: Profit Margin | B4: Grocery has the lowest profit margin at 20.1%. | C4: Home Appliance category has the highest average discount at 12.6%. | D4: High revenue may not convert into healthy profit. | E4: Review discount strategy and protect margin for low-profit categories.
A5: Product Dependency | B5: Top 5 products contribute 36.7% of total sales. | C5: Sales are concentrated on a small product group. | D5: Stockout in top products may cause sudden sales drop. | E5: Keep safety stock for top products and promote alternative products.
A6: Salesperson Performance Gap | B6: Top salesperson Rasel Uddin generated BDT 314,364; lowest salesperson Rumana Rahman generated BDT 103,337. | C6: Territory, lead quality, or skill gap may exist. | D6: Uneven performance creates dependency on few team members. | E6: Provide coaching to low performers and document top performer practices.

Sheet Sample_Dashboard
A1: Retail Sales Performance Dashboard - Sample Layout
A3: Total Sales | B3: =SUM(Fact_Sales!#REF!) -> #REF!
A4: Total Profit | B4: =SUM(Fact_Sales!S2:S1001) -> 3442170
A5: Achievement % | B5: =SUM(Fact_Sales!#REF!)/SUM(Fact_Sales!J2:J1001) -> #REF!
A6: Avg Delivery Days | B6: =AVERAGE(Fact_Sales!K2:K1001) -> 4.588
A7: Avg Rating | B7: =AVERAGE(Fact_Sales!L2:L1001) -> 3.5361
A10: Region_ID | B10: Region_Name | C10: Sales | D10: Target | E10: Achievement % | F10: Avg Delivery | G10: Avg Rating | I10: Category | J10: Sales | K10: Profit | L10: Profit Margin | M10: Avg Discount | N10: Qty Sold
A11: R01 | B11: Dhaka | C11: =SUMIF(Fact_Sales!$D$2:$D$1001,A11,Fact_Sales!#REF!) -> #REF! | D11: =SUMIF(Fact_Sales!$D$2:$D$1001,A11,Fact_Sales!$J$2:$J$1001) -> 1580413 | E11: =IFERROR(C11/D11,0) -> 0 | F11: =AVERAGEIF(Fact_Sales!$D$2:$D$1001,A11,Fact_Sales!$K$2:$K$1001) -> 2.96875 | G11: =AVERAGEIF(Fact_Sales!$D$2:$D$1001,A11,Fact_Sales!$L$2:$L$1001) -> 4.0609375 | I11: Electronics | J11: =SUMIF(Fact_Sales!#REF!,I11,Fact_Sales!#REF!) -> #REF! | K11: =SUMIF(Fact_Sales!#REF!,I11,Fact_Sales!$S$2:$S$1001) -> #REF! | L11: =IFERROR(K11/J11,0) -> 0 | M11: =AVERAGEIF(Fact_Sales!#REF!,I11,Fact_Sales!$I$2:$I$1001) -> #REF! | N11: =SUMIF(Fact_Sales!#REF!,I11,Fact_Sales!$H$2:$H$1001) -> #REF!
A12: R02 | B12: Chattogram | C12: =SUMIF(Fact_Sales!$D$2:$D$1001,A12,Fact_Sales!#REF!) -> #REF! | D12: =SUMIF(Fact_Sales!$D$2:$D$1001,A12,Fact_Sales!$J$2:$J$1001) -> 1495472 | E12: =IFERROR(C12/D12,0) -> 0 | F12: =AVERAGEIF(Fact_Sales!$D$2:$D$1001,A12,Fact_Sales!$K$2:$K$1001) -> 5.4566929 | G12: =AVERAGEIF(Fact_Sales!$D$2:$D$1001,A12,Fact_Sales!$L$2:$L$1001) -> 3.2433071 | I12: Home Appliance | J12: =SUMIF(Fact_Sales!#REF!,I12,Fact_Sales!#REF!) -> #REF! | K12: =SUMIF(Fact_Sales!#REF!,I12,Fact_Sales!$S$2:$S$1001) -> #REF! | L12: =IFERROR(K12/J12,0) -> 0 | M12: =AVERAGEIF(Fact_Sales!#REF!,I12,Fact_Sales!$I$2:$I$1001) -> #REF! | N12: =SUMIF(Fact_Sales!#REF!,I12,Fact_Sales!$H$2:$H$1001) -> #REF!
A13: R03 | B13: Sylhet | C13: =SUMIF(Fact_Sales!$D$2:$D$1001,A13,Fact_Sales!#REF!) -> #REF! | D13: =SUMIF(Fact_Sales!$D$2:$D$1001,A13,Fact_Sales!$J$2:$J$1001) -> 1147816 | E13: =IFERROR(C13/D13,0) -> 0 | F13: =AVERAGEIF(Fact_Sales!$D$2:$D$1001,A13,Fact_Sales!$K$2:$K$1001) -> 3.7884615 | G13: =AVERAGEIF(Fact_Sales!$D$2:$D$1001,A13,Fact_Sales!$L$2:$L$1001) -> 3.7884615 | I13: Fashion | J13: =SUMIF(Fact_Sales!#REF!,I13,Fact_Sales!#REF!) -> #REF! | K13: =SUMIF(Fact_Sales!#REF!,I13,Fact_Sales!$S$2:$S$1001) -> #REF! | L13: =IFERROR(K13/J13,0) -> 0 | M13: =AVERAGEIF(Fact_Sales!#REF!,I13,Fact_Sales!$I$2:$I$1001) -> #REF! | N13: =SUMIF(Fact_Sales!#REF!,I13,Fact_Sales!$H$2:$H$1001) -> #REF!
A14: R04 | B14: Rajshahi | C14: =SUMIF(Fact_Sales!$D$2:$D$1001,A14,Fact_Sales!#REF!) -> #REF! | D14: =SUMIF(Fact_Sales!$D$2:$D$1001,A14,Fact_Sales!$J$2:$J$1001) -> 1436830 | E14: =IFERROR(C14/D14,0) -> 0 | F14: =AVERAGEIF(Fact_Sales!$D$2:$D$1001,A14,Fact_Sales!$K$2:$K$1001) -> 4.2971014 | G14: =AVERAGEIF(Fact_Sales!$D$2:$D$1001,A14,Fact_Sales!$L$2:$L$1001) -> 3.6369565 | I14: Grocery | J14: =SUMIF(Fact_Sales!#REF!,I14,Fact_Sales!#REF!) -> #REF! | K14: =SUMIF(Fact_Sales!#REF!,I14,Fact_Sales!$S$2:$S$1001) -> #REF! | L14: =IFERROR(K14/J14,0) -> 0 | M14: =AVERAGEIF(Fact_Sales!#REF!,I14,Fact_Sales!$I$2:$I$1001) -> #REF! | N14: =SUMIF(Fact_Sales!#REF!,I14,Fact_Sales!$H$2:$H$1001) -> #REF!
A15: R05 | B15: Khulna | C15: =SUMIF(Fact_Sales!$D$2:$D$1001,A15,Fact_Sales!#REF!) -> #REF! | D15: =SUMIF(Fact_Sales!$D$2:$D$1001,A15,Fact_Sales!$J$2:$J$1001) -> 1507877 | E15: =IFERROR(C15/D15,0) -> 0 | F15: =AVERAGEIF(Fact_Sales!$D$2:$D$1001,A15,Fact_Sales!$K$2:$K$1001) -> 3.7461538 | G15: =AVERAGEIF(Fact_Sales!$D$2:$D$1001,A15,Fact_Sales!$L$2:$L$1001) -> 3.8230769 | I15: Beauty & Personal Care | J15: =SUMIF(Fact_Sales!#REF!,I15,Fact_Sales!#REF!) -> #REF! | K15: =SUMIF(Fact_Sales!#REF!,I15,Fact_Sales!$S$2:$S$1001) -> #REF! | L15: =IFERROR(K15/J15,0) -> 0 | M15: =AVERAGEIF(Fact_Sales!#REF!,I15,Fact_Sales!$I$2:$I$1001) -> #REF! | N15: =SUMIF(Fact_Sales!#REF!,I15,Fact_Sales!$H$2:$H$1001) -> #REF!
A16: R06 | B16: Barishal | C16: =SUMIF(Fact_Sales!$D$2:$D$1001,A16,Fact_Sales!#REF!) -> #REF! | D16: =SUMIF(Fact_Sales!$D$2:$D$1001,A16,Fact_Sales!$J$2:$J$1001) -> 1677860 | E16: =IFERROR(C16/D16,0) -> 0 | F16: =AVERAGEIF(Fact_Sales!$D$2:$D$1001,A16,Fact_Sales!$K$2:$K$1001) -> 5.3787879 | G16: =AVERAGEIF(Fact_Sales!$D$2:$D$1001,A16,Fact_Sales!$L$2:$L$1001) -> 3.2772727 | I16: Footwear | J16: =SUMIF(Fact_Sales!#REF!,I16,Fact_Sales!#REF!) -> #REF! | K16: =SUMIF(Fact_Sales!#REF!,I16,Fact_Sales!$S$2:$S$1001) -> #REF! | L16: =IFERROR(K16/J16,0) -> 0 | M16: =AVERAGEIF(Fact_Sales!#REF!,I16,Fact_Sales!$I$2:$I$1001) -> #REF! | N16: =SUMIF(Fact_Sales!#REF!,I16,Fact_Sales!$H$2:$H$1001) -> #REF!
A17: R07 | B17: Rangpur | C17: =SUMIF(Fact_Sales!$D$2:$D$1001,A17,Fact_Sales!#REF!) -> #REF! | D17: =SUMIF(Fact_Sales!$D$2:$D$1001,A17,Fact_Sales!$J$2:$J$1001) -> 1404174 | E17: =IFERROR(C17/D17,0) -> 0 | F17: =AVERAGEIF(Fact_Sales!$D$2:$D$1001,A17,Fact_Sales!$K$2:$K$1001) -> 6.4274194 | G17: =AVERAGEIF(Fact_Sales!$D$2:$D$1001,A17,Fact_Sales!$L$2:$L$1001) -> 2.9483871 | I17: Sports | J17: =SUMIF(Fact_Sales!#REF!,I17,Fact_Sales!#REF!) -> #REF! | K17: =SUMIF(Fact_Sales!#REF!,I17,Fact_Sales!$S$2:$S$1001) -> #REF! | L17: =IFERROR(K17/J17,0) -> 0 | M17: =AVERAGEIF(Fact_Sales!#REF!,I17,Fact_Sales!$I$2:$I$1001) -> #REF! | N17: =SUMIF(Fact_Sales!#REF!,I17,Fact_Sales!$H$2:$H$1001) -> #REF!
A18: R08 | B18: Mymensingh | C18: =SUMIF(Fact_Sales!$D$2:$D$1001,A18,Fact_Sales!#REF!) -> #REF! | D18: =SUMIF(Fact_Sales!$D$2:$D$1001,A18,Fact_Sales!$J$2:$J$1001) -> 1149207 | E18: =IFERROR(C18/D18,0) -> 0 | F18: =AVERAGEIF(Fact_Sales!$D$2:$D$1001,A18,Fact_Sales!$K$2:$K$1001) -> 4.5641026 | G18: =AVERAGEIF(Fact_Sales!$D$2:$D$1001,A18,Fact_Sales!$L$2:$L$1001) -> 3.5324786 | I18: Stationery | J18: =SUMIF(Fact_Sales!#REF!,I18,Fact_Sales!#REF!) -> #REF! | K18: =SUMIF(Fact_Sales!#REF!,I18,Fact_Sales!$S$2:$S$1001) -> #REF! | L18: =IFERROR(K18/J18,0) -> 0 | M18: =AVERAGEIF(Fact_Sales!#REF!,I18,Fact_Sales!$I$2:$I$1001) -> #REF! | N18: =SUMIF(Fact_Sales!#REF!,I18,Fact_Sales!$H$2:$H$1001) -> #REF!
I19: Kids & Toys | J19: =SUMIF(Fact_Sales!#REF!,I19,Fact_Sales!#REF!) -> #REF! | K19: =SUMIF(Fact_Sales!#REF!,I19,Fact_Sales!$S$2:$S$1001) -> #REF! | L19: =IFERROR(K19/J19,0) -> 0 | M19: =AVERAGEIF(Fact_Sales!#REF!,I19,Fact_Sales!$I$2:$I$1001) -> #REF! | N19: =SUMIF(Fact_Sales!#REF!,I19,Fact_Sales!$H$2:$H$1001) -> #REF!
I20: Furniture | J20: =SUMIF(Fact_Sales!#REF!,I20,Fact_Sales!#REF!) -> #REF! | K20: =SUMIF(Fact_Sales!#REF!,I20,Fact_Sales!$S$2:$S$1001) -> #REF! | L20: =IFERROR(K20/J20,0) -> 0 | M20: =AVERAGEIF(Fact_Sales!#REF!,I20,Fact_Sales!$I$2:$I$1001) -> #REF! | N20: =SUMIF(Fact_Sales!#REF!,I20,Fact_Sales!$H$2:$H$1001) -> #REF!
